{
    "file_path": "tests/test_models/test_validation.py",
    "content": "import pytest\nfrom pydantic import ValidationError\nfrom python_service.models import Race\n\ndef test_race_model_valid_data():\n    \"\"\"Tests that the Race model can be created with valid data.\"\"\"\n    race_data = {\n        'id': 'test_race_123',\n        'venue': 'Test Park',\n        'race_number': 1,\n        'start_time': '2025-10-20T12:00:00Z',\n        'runners': [],\n        'source': 'test_source'\n    }\n    race = Race(**race_data)\n    assert race.id == 'test_race_123'\n    assert race.venue == 'Test Park'\n\ndef test_race_model_invalid_data():\n    \"\"\"Tests that the Race model raises a ValidationError with invalid data.\"\"\"\n    invalid_race_data = {\n        'id': 'test_race_456',\n        'venue': 12345,  # Invalid type\n        'race_number': 'two', # Invalid type\n        'start_time': 'not-a-date',\n        'runners': 'not-a-list',\n        'source': 'test_source'\n    }\n    with pytest.raises(ValidationError):\n        Race(**invalid_race_data)\n"
}